<?xml version="1.0"?>
<robot name="leg_2dof">
  <link name="base_link">
    <visual>
      <geometry><box size="0.2 0.2 0.1"/></geometry>
      <material name="blue"><color rgba="0 0 1 1"/></material>
    </visual>
    <inertial>
      <mass value="2.0"/>
      <inertia ixx="0.01" ixy="0" ixz="0" iyy="0.01" iyz="0" izz="0.01"/>
    </inertial>
  </link>

  <joint name="hip_pitch" type="revolute">
    <parent link="base_link"/>
    <child link="thigh"/>
    <origin xyz="0 0 -0.05" rpy="0 0 0"/>
    <axis xyz="0 1 0"/> <limit lower="-1.57" upper="1.57" effort="30.0" velocity="5.0"/> </joint>

  <link name="thigh">
    <visual>
      <geometry><cylinder radius="0.03" length="0.3"/></geometry>
      <origin xyz="0 0 -0.15" rpy="0 0 0"/> <material name="red"><color rgba="1 0 0 1"/></material>
    </visual>
    <inertial>
      <mass value="1.0"/>
      <inertia ixx="0.005" ixy="0" ixz="0" iyy="0.005" iyz="0" izz="0.001"/>
    </inertial>
  </link>

  <joint name="knee_pitch" type="revolute">
    <parent link="thigh"/>
    <child link="calf"/>
    <origin xyz="0 0 -0.3" rpy="0 0 0"/> <axis xyz="0 1 0"/>
    <limit lower="-2.5" upper="0.0" effort="30.0" velocity="5.0"/> </joint>

  <link name="calf">
    <visual>
      <geometry><cylinder radius="0.02" length="0.3"/></geometry>
      <origin xyz="0 0 -0.15" rpy="0 0 0"/>
      <material name="green"><color rgba="0 1 0 1"/></material>
    </visual>
    <inertial>
      <mass value="0.5"/>
      <inertia ixx="0.002" ixy="0" ixz="0" iyy="0.002" iyz="0" izz="0.0005"/>
    </inertial>
  </link>
  <link name="foot_tip">
    <inertial>
      <mass value="0.0"/>
      <inertia ixx="0" ixy="0" ixz="0" iyy="0" iyz="0" izz="0"/>
    </inertial>
  </link>

  <joint name="foot_joint" type="fixed">
    <parent link="calf"/>
    <child link="foot_tip"/>
    <origin xyz="0 0 -0.3" rpy="0 0 0"/>
  </joint>
</robot>